Workbook
Name Comprar: [1]Param!#REF!
Name Comprar: [1]Param!#REF!
Name Comprar: [1]Param!#REF!
Name Comprar: [1]Param!#REF!
Name Comprar: [1]Param!#REF!
Name Comprar: [1]Param!#REF!
Name início_da_tarefa: [2]CronogramaDeProjeto!$E1
Name Início_do_projeto: '[3]Gráfico de Gantt'!$G$5
Name Início_do_projeto: '[3]Gráfico de Gantt'!$G$5
Name Início_do_projeto: '[4]Gráfico de Gantt'!$G$5
Name Início_do_projeto: '[4]Gráfico de Gantt'!$G$5
Name Início_do_projeto: '[3]Gráfico de Gantt'!$G$5
Name Início_do_projeto: '[4]Gráfico de Gantt'!$G$5
Name Início_do_projeto: '[3]Gráfico de Gantt'!$G$5
Name Início_do_projeto: '[4]Gráfico de Gantt'!$G$5
Name Início_do_projeto: '[5]Gráfico de Gantt'!$G$5
Name Início_do_projeto: '[3]Gráfico de Gantt'!$G$5
Name Início_do_projeto: '[6]Gráfico de Gantt'!$G$5
Name Início_do_projeto: 'Gráfico de Gantt'!$G$5
Name Periodicidade: [7]Param!$AB$5:$AB$9
Name progresso_da_tarefa: [2]CronogramaDeProjeto!$D1
Name Semana_de_exibição: '[3]Gráfico de Gantt'!$G$6
Name Semana_de_exibição: '[3]Gráfico de Gantt'!$G$6
Name Semana_de_exibição: '[4]Gráfico de Gantt'!$G$6
Name Semana_de_exibição: '[4]Gráfico de Gantt'!$G$6
Name Semana_de_exibição: '[3]Gráfico de Gantt'!$G$6
Name Semana_de_exibição: '[4]Gráfico de Gantt'!$G$6
Name Semana_de_exibição: '[3]Gráfico de Gantt'!$G$6
Name Semana_de_exibição: '[4]Gráfico de Gantt'!$G$6
Name Semana_de_exibição: '[5]Gráfico de Gantt'!$G$6
Name Semana_de_exibição: '[3]Gráfico de Gantt'!$G$6
Name Semana_de_exibição: '[6]Gráfico de Gantt'!$G$6
Name Semana_de_exibição: 'Gráfico de Gantt'!$G$6
Name Status: [1]Param!#REF!
Name término_da_tarefa: [2]CronogramaDeProjeto!$F1
Name VersaoExcel: [7]Param!$D$15:$E$15
Name VersaoSR: [7]Param!$C$24:$C$26

Sheet Project Charter

Sheet WBS-MACRO-ATIVIDADE

Sheet WBS_Detalhado (ordem etapas)
B7: 4.1 Plano de ação detalhado da WBS (com dependência, tempo e recurso)
B9: Ref | C9: Etapas – Atividades - | D9: Dependência | E9: Data Início | F9: Data Fim | G9: Duração em dias | H9: Conclusão | I9: Responsável | J9: Recursos | K9: Custos | L9: Obs
B10: 1 | C10: Iniciação | D10: 1 | E10: 45880 | F10: 45887 | G10: 8 | H10: 1ª | I10: GERENTE DE PROJETO | J10: PESSOAS
B11: 1A | C11: DEFINIÇÃO DE OBJETIVOS DO PROJETO | D11: 1 | E11: 45880 | F11: 45884 | G11: 5 | H11: 1ª | I11: GERENTE DE PROJETO | J11: PESSOAS | K11: 5000
B12: 1B | C12: FORMAÇÃO DA EQUIPE DE DESIGN E DESENVOLVIMENTO | D12: 1A | E12: 45884 | F12: 45885 | G12: 1 | H12: 1ª | I12: GERENTE DE PROJETO | J12: PESSOAS | K12: 1000
B13: 1C | C13: IDENTIFICAÇÃO DE FUNCIONALIDADES E RECURSOS | D13: 1A | E13: 45884 | F13: 45887 | G13: 3 | H13: 1ª | I13: GERENTE DE PROJETO | J13: PESSOAS | K13: 3000
B14: 1D | C14: IDENTIFICAÇÃO DE STAKEHOLDERS | D14: 1A | E14: 45884 | F14: 45885 | G14: 1 | H14: 1ª | I14: GERENTE DE PROJETO | J14: PESSOAS | K14: 1000
B15: 2 | C15: Planejamento | D15: 1C | E15: 45887 | F15: 45893 | G15: 10 | H15: 2ª | I15: GERENTE DE PROJETO | J15: PESSOAS | K15: =SUM(K11:K14) -> 10000
B16: 2A | C16: ANÁLISE DE MERCADO | D16: 2 | E16: 45887 | F16: 45888 | G16: 1 | H16: 2ª | I16: GERENTE DE PROJETO | J16: PESSOAS | K16: 2000
B17: 2B | C17: LEVANTAMENTO DE REQUISITOS | D17: 2A | E17: 45889 | F17: 45891 | G17: 2 | H17: 2ª | I17: GERENTE DE PROJETO | J17: PESSOAS | K17: 2000
B18: 2C | C18: DOCUMENTAÇÃO DE REQUISITOS FUNCIONAIS | D18: 2A | E18: 45889 | F18: 45891 | G18: 2 | H18: 2ª | I18: GERENTE DE PROJETO | J18: PESSOAS | K18: 1000
B19: 2D | C19: DOCUMENTAÇÃO DE REQUISITOS NÃO FUNCIONAIS | D19: 2A | E19: 45889 | F19: 45891 | G19: 2 | H19: 2ª | I19: GERENTE DE PROJETO | J19: PESSOAS | K19: 1000
B20: 2E | C20: IDENTIFICAÇÃO DO CAMINHO CRÍTICO | D20: 2B,2C,2D | E20: 45892 | F20: 45893 | G20: 1 | H20: 2ª | I20: GERENTE DE PROJETO | J20: PESSOAS | K20: 1000
B21: 2F | C21: PLANEJAMENTO DE SEGURANÇA E LGPD | D21: 2B,2C,2D | E21: 45892 | F21: 45893 | G21: 1 | H21: 2ª | I21: GERENTE DE PROJETO | J21: PESSOAS | K21: 2000
B22: 2G | C22: DEFINIÇÃO DE PROTOCOLOS DE PRIVACIDADE (DADOS) | D22: 2B,2C,2D | E22: 45892 | F22: 45893 | G22: 1 | H22: 2ª | I22: GERENTE DE PROJETO | J22: PESSOAS | K22: 3000
B23: 3 | C23: Design e Prototipagem | D23: 2B,2E,2F,2G | E23: 45894 | F23: 45902 | G23: 19 | H23: 3ª | I23: DESIGN | J23: PESSOAS + SOFTWARE | K23: =SUM(K16:K22) -> 12000
B24: 3A | C24: REALIZAR O DESIGN DA INTERFACE DO USUÁRIO(UI) | D24: 3 | E24: 45894 | F24: 45897 | G24: =F24-E24 -> 3 | H24: 3ª | I24: DESIGN | J24: PESSOAS + SOFTWARE | K24: 2000
B25: 3B | C25: DEFINIR PALETA DE CORES E TIPOGRAFIA | D25: 3A | E25: 45894 | F25: 45894 | G25: 1 | H25: 3ª | I25: DESIGN | J25: PESSOAS + SOFTWARE | K25: 1000
B26: 3C | C26: CRIAR ÍCONES E ELEMENTOS VISUAIS | D26: 3A | E26: 45894 | F26: 45894 | G26: 1 | H26: 3ª | I26: DESIGN | J26: PESSOAS + SOFTWARE | K26: 1000
B27: 3D | C27: GARANTIR CONSISTÊNCIA VISUAL | D27: 3A | E27: 45894 | F27: 45897 | G27: =F27-E27 -> 3 | H27: 3ª | I27: DESIGN | J27: PESSOAS + SOFTWARE | K27: 1000
B28: 3E | C28: CRIAÇÃO DE PROTÓTIPO INTERATIVO | D28: 3D | E28: 45894 | F28: 45898 | G28: =F28-E28 -> 4 | H28: 3ª | I28: DESIGN | J28: PESSOAS + SOFTWARE | K28: 1000
B29: 3F | C29: EXPERIÊNCIA DO USUÁRIO (UX) | D29: 3D | E29: 45894 | F29: 45898 | G29: =F29-E29 -> 4 | H29: 3ª | I29: DESIGN | J29: PESSOAS + SOFTWARE | K29: 2000
B30: 3G | C30: DEFINIÇÃO DE PERSONAS | D30: 3F | E30: 45898 | F30: 45899 | G30: =F30-E30 -> 1 | H30: 3ª | I30: DESIGN | J30: PESSOAS + SOFTWARE | K30: 4000
B31: 3H | C31: GARANTIR ACESSIBILIDADE E USABILIDADE | D31: 3F | E31: 45901 | F31: 45902 | G31: =F31-E31 -> 1 | H31: 3ª | I31: DESIGN | J31: PESSOAS + SOFTWARE | K31: 1000
B32: 3I | C32: MAPEAR JORNADA DO USUÁRIO | D32: 3E | E32: 45901 | F32: 45902 | G32: =F32-E32 -> 1 | H32: 3ª | I32: DESIGN | J32: PESSOAS + SOFTWARE | K32: 2000
B33: 3J | C33: VALIDAÇÃO INICIAL COM STAKEHOLDERS | D33: 3H,3F,3E | E33: 45901 | F33: 45902 | G33: 1 | H33: 3ª | I33: DESIGN | J33: PESSOAS + SOFTWARE | K33: 1000
B34: 4 | C34: Desenvolvimento | D34: 3J | E34: 45903 | F34: 45940 | G34: 42 | H34: 4ª | I34: DESENVOLVIMENTO | J34: PESSOAS + SOFTWARE + HADWARE | K34: =SUM(K24:K33) -> 16000
B35: 4A | C35: DEFINIR A ESTRUTURA DO SITE | D35: 4 | E35: 45903 | F35: 45904 | G35: =F35-E35 -> 1 | H35: 4ª | I35: DESENVOLVIMENTO | J35: PESSOAS + SOFTWARE + HADWARE | K35: 2000
B36: 4B | C36: PREPARAÇÃO DO AMBIENTE | D36: 4A | E36: 45903 | F36: 45904 | G36: =F36-E36 -> 1 | H36: 4ª | I36: DESENVOLVIMENTO | J36: PESSOAS + SOFTWARE + HADWARE | K36: 1000
B37: 4C | C37: CONFIGURAÇÃO DE REPOSITÓRIO GITHUB | D37: 4A | E37: 45903 | F37: 45904 | G37: =F37-E37 -> 1 | H37: 4ª | I37: DESENVOLVIMENTO | J37: PESSOAS + SOFTWARE + HADWARE | K37: 1000
B38: 4D | C38: DEFINIÇÃO DO AMBIENTE DE HOSPEDAGEM | D38: 4A | E38: 45903 | F38: 45904 | G38: =F38-E38 -> 1 | H38: 4ª | I38: DESENVOLVIMENTO | J38: PESSOAS + SOFTWARE + HADWARE | K38: 10000
B39: 4E | C39: INSTALAÇÃO DO ETL E BI | D39: 4A | E39: 45903 | F39: 45904 | G39: =F39-E39 -> 1 | H39: 4ª | I39: DESENVOLVIMENTO | J39: PESSOAS + SOFTWARE + HADWARE | K39: 1000
B40: 4F | C40: CÓDIGO FRONT-END | D40: 4A | E40: 45905 | F40: 45919 | G40: =F40-E40 -> 14 | H40: 4ª | I40: DESENVOLVIMENTO | J40: PESSOAS + SOFTWARE + HADWARE | K40: 2000
B41: 4G | C41: ESTRUTURAÇÃO INICIAL DE INTERFACE | D41: 4F | E41: 45905 | F41: 45919 | G41: =F41-E41 -> 14 | H41: 4ª | I41: DESENVOLVIMENTO | J41: PESSOAS + SOFTWARE + HADWARE | K41: 1000
B42: 4H | C42: IMPLEMENTAÇÃO DE KPIs PRINCIPAIS | D42: 4G | E42: 45905 | F42: 45919 | G42: =F42-E42 -> 14 | H42: 4ª | I42: DESENVOLVIMENTO | J42: PESSOAS + SOFTWARE + HADWARE | K42: 1000
B43: 4I | C43: CRIAÇÃO DE GRÁFICOS INTERATIVOS | D43: 4G | E43: 45905 | F43: 45919 | G43: =F43-E43 -> 14 | H43: 4ª | I43: DESENVOLVIMENTO | J43: PESSOAS + SOFTWARE + HADWARE | K43: 3000
B44: 4J | C44: DESENVOLVIMENTO DE FILTROS DINÂMICOS | D44: 4I | E44: 45905 | F44: 45919 | G44: =F44-E44 -> 14 | H44: 4ª | I44: DESENVOLVIMENTO | J44: PESSOAS + SOFTWARE + HADWARE | K44: 2000
B45: 4K | C45: EXPORTAÇÃO DE RELATÓRIOS | D45: 4J | E45: 45905 | F45: 45919 | G45: =F45-E45 -> 14 | H45: 4ª | I45: DESENVOLVIMENTO | J45: PESSOAS + SOFTWARE + HADWARE | K45: 1000
B46: 4L | C46: CÓDIGO BACK-END | D46: 3E,2G | E46: 45898 | F46: 45940 | G46: =F46-E46 -> 42 | H46: 4ª | I46: DESENVOLVIMENTO | J46: PESSOAS + SOFTWARE + HADWARE | K46: 4000
B47: 4M | C47: ESTRUTURAÇÃO DO BANCO DE DADOS | D47: 2G | E47: 45899 | F47: 45940 | G47: =F47-E47 -> 41 | H47: 4ª | I47: DESENVOLVIMENTO | J47: PESSOAS + SOFTWARE + HADWARE | K47: 1000
...

Sheet WBS_Detalhado (ordem depend)
B6: 4.2 Plano de ação detalhado da WBS (com dependência, tempo e recurso)
B8: Ref | C8: Etapas – Atividades - | D8: Dependência | E8: Duração em semanas | F8: Conclusão | G8: Responsável | H8: Recursos | I8: Obs
B9: 1A | C9: DEFINIÇÃO DOS OBJETIVOS DO PROJETO | E9: 1 | F9: 1ª | G9: GERENTE DE PROJETO | H9: Pessoas | I9: -
B10: 1B | C10: FORMAÇÃO DA EQUIPE DO PROJETO | D10: 1A | E10: 1 | F10: 1ª | G10: GERENTE DE PROJETO | H10: Pessoas | I10: -
B11: 1C | C11: IDENTIFICAÇÃO DOS STAKEHOLDERS | D11: 1A | E11: 1 | F11: 1ª | G11: GERENTE DE PROJETO | H11: Pessoas
B12: 1E | C12: REUNIÃO DE KICK-OFF | D12: 1A | E12: 1 | F12: 1ª | G12: GERENTE DE PROJETO | H12: Pessoas
B13: 2A | C13: LEVANTAMENTO DE REQUISITOS | D13: 1A | E13: 2 | F13: 2ª | G13: GERENTE DE PROJETO | H13: Pessoas | I13: -
B14: 2B | C14: ENTREVISTAS COM CANNOLI E RESTAURANTES | D14: 2A | E14: 2 | F14: 2ª | G14: GERENTE DE PROJETO | H14: Pessoas | I14: -
B15: 2C | C15: DOCUMENTAÇÃO DE REQUISITOS FUNCIONAIS | D15: 2A | E15: 2 | F15: 1ª | G15: GERENTE DE PROJETO | H15: Pessoas | I15: -
B16: 2D | C16: DOCUMENTAÇÃO DE REQUISITOS NÃO FUNCIONAIS | D16: 2A | E16: 2 | F16: 1ª | G16: GERENTE DE PROJETO | H16: Pessoas | I16: -
B17: 2E | C17: DEFINIÇÃO DO ESCOPO DETALHADO (LIMITES, PREMISSAS, RESTRIÇÕES) | D17: 2B,2C,2D | E17: 1 | F17: 2ª | G17: GERENTE DE PROJETO | H17: Pessoas | I17: -
B18: 2F | C18: CRONOGRAMA E MARCOS DO PROJETO | D18: 2B,2C,2D | E18: 1 | F18: 1ª | G18: GERENTE DE PROJETO | H18: Pessoas | I18: -
B19: 2G | C19: PLANEJAMENTO DE SEGURANÇA E LGPD | D19: 2B,2C,2D | E19: 1 | F19: 1ª | G19: GERENTE DE PROJETO | H19: Pessoas | I19: -
B20: 3A | C20: UX – EXPERIÊNCIA DO USUÁRIO | D20: 2A | E20: 1 | F20: 1ª | G20: DESIGN | H20: Pessoas + software | I20: -
B21: 3B | C21: DEFINIÇÃO DE PERSONAS (ADMIN / RESTAURANTE) | D21: 3A | E21: 1 | F21: 1ª | G21: DESIGN | H21: Pessoas + software | I21: -
B22: 3C | C22: JORNADA DO USUÁRIO | D22: 3A | E22: 1 | F22: 1ª | G22: DESIGN | H22: Pessoas + software | I22: -
B23: 3D | C23: UI – INTERFACE DO USUÁRIO | D23: 3A | E23: 1 | F23: 2ª | G23: DESIGN | H23: Pessoas + software | I23: -
B24: 3E | C24: DEFINIÇÃO DE PALETA DE CORES E TIPOGRAFIA | D24: 3D | E24: 1 | F24: 2ª | G24: DESIGN | H24: Pessoas + software | I24: -
... B49: 5E | C49: ATUALIZAÇÃO EM TEMPO REAL (OU SIMULAÇÃO) | D49: 5D | E49: 3 | F49: 2ª | G49: DESENVOLVIMENTO | H49: Pessoas + software + hardware | I49: -
B50: 6A | C50: TESTES UNITÁRIOS (CÓDIGO E MÓDULOS) | D50: 5E | E50: 3 | F50: 2ª | G50: DESENVOLVIMENTO | H50: Pessoas + software + hardware
B51: 6B | C51: TESTES INTEGRADOS (ETL + DASHBOARD + CHATBOT) | D51: 6A | E51: 3 | F51: 2ª | G51: DESENVOLVIMENTO | H51: Pessoas + software + hardware
B52: 6C | C52: TESTES DE SEGURANÇA (LGPD, CRIPTOGRAFIA, LOGIN) | D52: 6B | E52: 3 | F52: 2ª | G52: DESENVOLVIMENTO | H52: Pessoas + software + hardware
B53: 6D | C53: TESTES DE USABILIDADE E RESPONSIVIDADE | D53: 6C | E53: 3 | F53: 2ª | G53: DESENVOLVIMENTO | H53: Pessoas + software + hardware
B54: 6E | C54: HOMOLOGAÇÃO COM A CANNOLI | D54: 6D | E54: 1 | F54: 2ª | G54: EQUIPE TÉCNICA | H54: Pessoas
B55: 6F | C55: VALIDAÇÃO COM RESTAURANTES PARCEIROS | D55: 6E | E55: 1 | F55: 2ª | G55: EQUIPE TÉCNICA | H55: Pessoas
B56: 6G | C56: TREINAMENTO DE STAKEHOLDERS | D56: 6F | E56: 1 | F56: 2ª | G56: EQUIPE TÉCNICA | H56: Pessoas
B57: 7A | C57: DEPLOY DA SOLUÇÃO NA NUVEM | D57: 6G | E57: 1 | F57: 2ª | G57: EQUIPE TÉCNICA | H57: Pessoas
B58: 7B | C58: ENTREGA OFICIAL DA SOLUÇÃO | D58: 7A | E58: 1 | F58: 2ª | G58: EQUIPE TÉCNICA | H58: Pessoas
B59: 7C | C59: COLETA DE FEEDBACK INICIAL | D59: 7B | E59: 1 | F59: 2ª | G59: EQUIPE TÉCNICA | H59: Pessoas
B60: 7D | C60: RELATÓRIO FINAL DO PROJETO | D60: 7C | E60: 1 | F60: 2ª | G60: EQUIPE TÉCNICA | H60: Pessoas
B61: 7E | C61: DOCUMENTAÇÃO COMPLETA | D61: 7D | E61: 1 | F61: 2ª | G61: EQUIPE TÉCNICA | H61: Pessoas
B62: 7F | C62: AVALIAÇÃO DE RESULTADOS | D62: 7E | E62: 1 | F62: 2ª | G62: EQUIPE TÉCNICA | H62: Pessoas

Sheet Análise do Stakeholder
A8: Entregas do Projeto | B8: A definir | C8: Atulizado Em | D8: 45916
A10: SAM | I10: SRM
A11: Stakeholder | B11: Objetivos | C11: Metas | D11: Motivações e Interesses | E11: Poder e influência | F11: Importância e Impacto | G11: Papéis & Responsabilidades | H11: Sintonia "fina" | I11: Área de Interesse | J11: Nível de Detalhe | K11: Formato | L11: Frequência | M11: Mecanismo de Entrega
A12: Cliente (Usuários Finais) Cannoli | B12: Ter visibilidade das ações de marketing implementadas | C12: Controle total de ações e impactos nos consuidores | D12: Clareza nas informações | E12: Influenciam o sucesso do dashboard por meio do uso e feedback. | F12: Cruciais para a aceitação e popularidade do dashboard. | G12: Usar o dashboard, fornecer feedback, compartilhar experiências. | H12: Garantir que o dashboard atenda às suas necessidades. | I12: Relatórios sobre atualizações de recursos, melhorias com base no feedback dos usuários, dicas de uso do aplicativo. | J12: Relatórios concisos e informativos, destacando as principais entregas. | K12: Comunicar funções do produto via apresentação | L12: Entrega única
A13: Product Owner | B13: Desenvolver um aplicativo bem-sucedido que atenda às necessidades da Cannoli. | C13: Entrega de dashboard funcional que atenda as necessiades de controle da Cannoli | D13: Inovação na exposição de dados. | E13: Determina a direção e as prioridades do desenvolvimento. | F13: Fundamental para o sucesso do aplicativo. | G13: Definir a visão do produto, priorizar recursos, tomar decisões estratégicas. | H13: Alinhar o desenvolvimento com as necessidades das entregas. | I13: Relatórios de desempenho do aplicativo, métricas-chave, status do desenvolvimento. | J13: Relatórios detalhados com métricas específicas e análise de tendências. | K13: Reuniões semanal de revisão de entregas. | L13: Dailys durante a sprint e as demais reuniões do scrum. | M13: Reuniões remotas, e presenciais e manutenção do github board.
A14: Desenvolvedores | B14: Criar um da funcional e confiável. | C14: Criar a ferramenta e garantir a boa funcionalidade da mesma | D14: Desenvolvimento de dashboard e pipelines de dados. | E14: Impactam diretamente na definição de tecnologias implementadas no produto. | F14: Contribuem para a usabilidade e confiabilidade do dashboard. | G14: Escrever código, realizar testes, resolver problemas técnicos. | H14: Colaboração eficaz com o Product Owner para implementar recursos necessários com sucesso. | I14: Atualizações de prioridades de desenvolvimento, correções de bugs, novos recursos planejados. | J14: Comunicados claros e específicos sobre o que precisa ser desenvolvido. | K14: Alinhamentos semanais de sprint com a equipe de desenvolvimento e produto. | L14: Dailys durante a sprint e as demais reuniões do scrum. | M14: Reuniões virtuais, quadro de tarefas online no github.
A15: Restaurantes Parceiros | B15: Ter relatórios claros e confiaveis para auxiliar na tomada de decisão e gestão | C15: Mensurar com precisão as interações dos clietes (visitas, compras) e ter acesso transparente aos dados. | D15: Melhorar a gestão do negócio e entender o comportamento dos consumidores para aumentar a competitividade. | E15: São os usuários finais e fornecedores de dados. | F15: Solução é criada para atender as suas necessidades. A satisfação deles valida o sucesso do projeto. | G15: Utilizar os relatórios para avaliar o impacto da aplicação. | I15: Benefício da ferramenta, como usar o dash e fomo fornecer informações complementares. | J15: Direto, claro e focado no uso do dashboard | K15: Manuais e treinamentos. | L15: conforme às entregas definidas | M15: Via web.
A16: Patrocinadores | B16: Garantir que o projeto seja entregue com sucesso e que o investimento seja bem utilizado | C16: Ver o projeto sendo entregue conforme o planejado. | D16: Sucesso da solução e potencial futuro. | E16: Fornecem os recursos financeiros. | F16: Apoio na contrução de estruturas físicas de apresentação do projeto. | G16: Prover recursos. | H16: Validar retorno conforme as expectativas iniciais. | I16: Status geral do projeto. | J16: Avaliação de KPIs | K16: Apresentação de Status | L16: Mensal/ a cada entrega. | M16: Reuniões virtuais e ou presenciais.

Sheet REDE PERT
C3: Ref | D3: Etapas – Atividades - | E3: Dependência | F3: Duração em semanas
C4: 1A | D4: DEFINIÇÃO DOS OBJETIVOS DO PROJETO | F4: 1
C5: 1B | D5: FORMAÇÃO DA EQUIPE DO PROJETO | E5: 1A | F5: 1
C6: 1C | D6: IDENTIFICAÇÃO DOS STAKEHOLDERS | E6: 1A | F6: 1
C7: 1E | D7: REUNIÃO DE KICK-OFF | E7: 1A | F7: 1
C8: 2A | D8: LEVANTAMENTO DE REQUISITOS | E8: 1A | F8: 2
C9: 2B | D9: ENTREVISTAS COM CANNOLI E RESTAURANTES | E9: 2A | F9: 2
C10: 2C | D10: DOCUMENTAÇÃO DE REQUISITOS FUNCIONAIS | E10: 2A | F10: 2
C11: 2D | D11: DOCUMENTAÇÃO DE REQUISITOS NÃO FUNCIONAIS | E11: 2A | F11: 2
C12: 2E | D12: DEFINIÇÃO DO ESCOPO DETALHADO (LIMITES, PREMISSAS, RESTRIÇÕES) | E12: 2B,2C,2D | F12: 1
C13: 2F | D13: CRONOGRAMA E MARCOS DO PROJETO | E13: 2B,2C,2D | F13: 1
C14: 2G | D14: PLANEJAMENTO DE SEGURANÇA E LGPD | E14: 2B,2C,2D | F14: 1
C15: 3A | D15: UX – EXPERIÊNCIA DO USUÁRIO | E15: 2A | F15: 1
C16: 3B | D16: DEFINIÇÃO DE PERSONAS (ADMIN / RESTAURANTE) | E16: 3A | F16: 1
... C57: 7F | D57: AVALIAÇÃO DE RESULTADOS | E57: 7E | F57: 1

Sheet Gestão de Custo
B2: Previsões de Orçamento | J2: Saúde e Bem Estar
C4: 1 | D4: Capa | F4: Instruções, Histórico de Alterações e as Aprovações
C5: =C4+1 -> 2 | D5: Orçado | F5: Detalhamento dos investimentos orçados
C6: =C5+1 -> 3 | D6: Realizado | F6: Detalhamento dos investimentos realizados
C7: =C6+1 -> 4 | D7: Status | F7: Status comparando Orçado x Realizado
C8: =C7+1 -> 5 | D8: Parâmetros | F8: Parâmetros usados nas outras abas da planilha.
D10: Fonte | E10: https://escritoriodeprojetos.com.br/download/previsoes-do-orcamento/
B14: Controle de Versões
B15: Versão | C15: Data | D15: Autor | E15: Notas da Revisão
B16: 1
B17: 2
B20: Instruções | D20: =TODAY() -> 45971
B21: Ref. | C21: Aba | D21: Respons | E21: Passos
B22: 0 | C22: Param | D22: PMO | E22: Entre com o Custo do Capital
B23: 1 | C23: Orçado | D23: Gerente de Projetos | E23: Preencher as informações de identificação do projeto (Nome, Solicitante e Patrocionador)
B24: =B23+1 -> 2 | C24: Orçado | D24: Gerente de Projetos | E24: Preencher na coluna B o nome de cada Gasto (B7, B10, ...). No máximo 5, caso tiver mais de 5 agrupar os benefícios ou ajustar planilha. Veja na Aba Param - Coluna C - Tipos de gastos comuns em projetos
B25: =B24+1 -> 3 | C25: Orçado | D25: Gerente de Projetos | E25: Sempre que possível, esclareça como foi calculado o valor dos gastos (C7, C10, ...)
B26: =B25+1 -> 4 | C26: Orçado | D26: Gerente de Projetos | E26: Entrar com o valor dos gastos por ano (D9..M21), se preferir, entre com o valor do crescimento por ano (D8..M20) para todos os gastos
B27: =B26+1 -> 5 | C27: Orçado | D27: Gerente de Projetos | E27: Preenche na coluna B o nome dos custos (B29, B30)
B28: =B27+1 -> 6 | C28: Orçado | D28: Gerente de Projetos | E28: Sempre que possível, esclareça como foi calculado o valor dos custos (C29, C30)
B29: =B28+1 -> 7 | C29: Orçado | D29: Gerente de Projetos | E29: Entrar com o valor dos custos por ano (D27..M31)
B30: =B29+1 -> 8 | C30: Realizado | D30: Gerente de Projetos | E30: Entre com o valor realizado mês a mês. Caso não necessitar registrar os detalhes, pode incluir o valor total na linha 39 [Investimento total]
B31: =B30+1 -> 9
B32: =B31+1 -> 10
B33: =B32+1 -> 11
B34: =B33+1 -> 12
B36: Aprovações
B37: Ref. | C37: Data | D37: Participante | E37: Assinatura
B38: 1
B39: 2
B40: 3

Sheet Orcado
B2: Identificação do Projeto | D2: Mês
B3: Nome do Projeto | C3: =Param!C17 -> PI ADS4 - 2025 | E3: =Param!C18 -> 45891 | F3: =DATE(YEAR(E3),MONTH(E3)+1,DAY(E3)) -> 45922 | G3: =DATE(YEAR(F3),MONTH(F3)+1,DAY(F3)) -> 45952 | H3: =DATE(YEAR(G3),MONTH(G3)+1,DAY(G3)) -> 45983 | I3: =DATE(YEAR(H3),MONTH(H3)+1,DAY(H3)) -> 46013 | J3: =DATE(YEAR(I3),MONTH(I3)+1,DAY(I3)) -> 46044 | K3: =DATE(YEAR(J3),MONTH(J3)+1,DAY(J3)) -> 46075 | L3: =DATE(YEAR(K3),MONTH(K3)+1,DAY(K3)) -> 46103 | M3: =DATE(YEAR(L3),MONTH(L3)+1,DAY(L3)) -> 46134 | ... P3: =DATE(YEAR(O3),MONTH(O3)+1,DAY(O3)) -> 46225 | Q3: TOTAL
B4: Patrocinador | C4: =Param!C19 -> Cannoli | D4: 0 | E4: 1 | F4: =E4+1 -> 2 | G4: =F4+1 -> 3 | H4: =G4+1 -> 4 | I4: =H4+1 -> 5 | J4: =I4+1 -> 6 | K4: =J4+1 -> 7 | L4: =K4+1 -> 8 | M4: =L4+1 -> 9 | ... P4: =O4+1 -> 12
B5: Investimento inicial Total | C5: 110000 | D5: =SUM(D9+D11+D13+D15+D17+D19+D21+D23+D25+D27+D29) -> 110000 | E5: =SUM(E33:E46)+E9+E11+E13+E15+E17+E19+E21+E23+E25+E27+E29 -> 10388.23 | F5: =SUM(F33:F46)+F9+F11+F13+F15+F17+F19+F21+F23+F25+F27 -> 10305.458 | G5: =SUM(G33:G46)+G9+G11+G13+G15+G17+G19+G21+G23+G25+G27 -> 7986.0038 | H5: =SUM(H33:H46)+H9+H11+H13+H15+H17+H19+H21+H23+H25+H27 -> 8234.6042 | I5: =SUM(I33:I46)+I9+I11+I13+I15+I17+I19+I21+I23+I25+I27 -> 9058.0646 | J5: =SUM(J33:J46)+J9+J11+J13+J15+J17+J19+J21+J23+J25+J27 -> 9963.8711 | K5: =SUM(K33:K46)+K9+K11+K13+K15+K17+K19+K21+K23+K25+K27 -> 10960.258 | L5: =SUM(L33:L46)+L9+L11+L13+L15+L17+L19+L21+L23+L25+L27 -> 12056.284 | M5: =SUM(M33:M46)+M9+M11+M13+M15+M17+M19+M21+M23+M25+M27 -> 13261.912 | ... P5: =SUM(P33:P46)+P9+P11+P13+P15+P17+P19+P21+P23+P25+P27 -> 17651.605 | Q5: =SUM(D5:P5) -> 250501.31
B6: Investimento Acumulado | C6: 0 | D6: =D5 -> 110000 | E6: =D6+E5 -> 120388.23 | F6: =E6+F5 -> 130693.69 | G6: =F6+G5 -> 138679.69 | H6: =G6+H5 -> 146914.3 | I6: =H6+I5 -> 155972.36 | J6: =I6+J5 -> 165936.23 | K6: =J6+K5 -> 176896.49 | L6: =K6+L5 -> 188952.77 | ... P6: =O6+P5 -> 250501.31
B7: Orçado | C7: Explicação
B8: Investimento c/ taxa de crescimento | C8: Para facilitar o cálculo do gasto baseado em uma taxa de crescimento.
B9: Iniciação | C9: Gasto referente ao start do projeto, desde o estudo, mapeamento de funcionalidade e formação de time | D9: 10000 | E9: 3500 | F9: =E9*(1+F8) -> 3500 | G9: 500 | H9: 0 | I9: =H9*(1+I8) -> 0 | J9: =I9*(1+J8) -> 0 | K9: =J9*(1+K8) -> 0 | L9: =K9*(1+L8) -> 0 | M9: =L9*(1+M8) -> 0 | N9: =M9*(1+N8) -> 0 | O9: =N9*(1+O8) -> 0 | P9: =O9*(1+P8) -> 0 | Q9: =SUM(E9:P9) -> 7500
B10: Taxa de Crescimento de 10% | C10: Taxa de crescimento de investimento de 10% ao mês MOM | F10: 0.1 | G10: =F10 -> 0.1 | H10: =G10 -> 0.1 | I10: =H10 -> 0.1 | J10: =I10 -> 0.1 | K10: =J10 -> 0.1 | L10: =K10 -> 0.1 | M10: =L10 -> 0.1 | N10: =M10 -> 0.1 | ... P10: =O10 -> 0.1
B11: Planejamento | C11: Tudo que tange o mapeamento inicial do planejamento, como plano de exercicio e requisitos, mapas de academias e parques e afins. | D11: 12000 | E11: 794.96 | F11: =E11*(1+F10) -> 874.456 | G11: =F11*(1+G10) -> 961.9016 | H11: =G11*(1+H10) -> 1058.0918 | I11: =H11*(1+I10) -> 1163.9009 | J11: =I11*(1+J10) -> 1280.291 | K11: =J11*(1+K10) -> 1408.3201 | L11: =K11*(1+L10) -> 1549.1521 | M11: =L11*(1+M10) -> 1704.0674 | ... P11: =O11*(1+P10) -> 2268.1137 | Q11: =SUM(E11:P11) -> 16999.65
B12: Taxa de Crescimento de 10% | C12: Taxa de crescimento de investimento de 10% ao mês MOM | F12: 0.1 | G12: =F12 -> 0.1 | H12: =G12 -> 0.1 | I12: =H12 -> 0.1 | J12: =I12 -> 0.1 | K12: =J12 -> 0.1 | L12: =K12 -> 0.1 | M12: =L12 -> 0.1 | N12: =M12 -> 0.1 | ... P12: =O12 -> 0.1
B13: Design e Prototipagem | C13: Todo processo que compete ao desenvolvimento da funcionalidade em sua camada de Wire, Layout, experiência, ou seja, UX. | D13: 16000 | E13: 617.29 | F13: =E13*(1+F12) -> 679.019 | G13: =F13*(1+G12) -> 746.9209 | H13: =G13*(1+H12) -> 821.61299 | I13: =H13*(1+I12) -> 903.77429 | J13: =I13*(1+J12) -> 994.15172 | K13: =J13*(1+K12) -> 1093.5669 | L13: =K13*(1+L12) -> 1202.9236 | M13: =L13*(1+M12) -> 1323.2159 | ... P13: =O13*(1+P12) -> 1761.2004 | Q13: =SUM(E13:P13) -> 13200.305
B14: Taxa de Crescimento de 10% | C14: Taxa de crescimento de investimento de 10% ao mês MOM | F14: 0.1 | G14: =F14 -> 0.1 | H14: =G14 -> 0.1 | I14: =H14 -> 0.1 | J14: =I14 -> 0.1 | K14: =J14 -> 0.1 | L14: =K14 -> 0.1 | M14: =L14 -> 0.1 | N14: =M14 -> 0.1 | ... P14: =O14 -> 0.1
B15: Desenvolvimento | C15: Desenvolvimento do frontend, backend e todo processo de desenvolvimento. | D15: 40000 | E15: 1496.43 | F15: =E15*(1+F14) -> 1646.073 | G15: =F15*(1+G14) -> 1810.6803 | H15: =G15*(1+H14) -> 1991.7483 | I15: =H15*(1+I14) -> 2190.9232 | J15: =I15*(1+J14) -> 2410.0155 | K15: =J15*(1+K14) -> 2651.017 | L15: =K15*(1+L14) -> 2916.1187 | M15: =L15*(1+M14) -> 3207.7306 | ... P15: =O15*(1+P14) -> 4269.4894 | Q15: =SUM(E15:P15) -> 32000.084
B16: Taxa de Crescimento de 10% | C16: Taxa de crescimento de investimento de 10% ao mês MOM | F16: 0.1 | G16: =F16 -> 0.1 | H16: =G16 -> 0.1 | I16: =H16 -> 0.1 | J16: =I16 -> 0.1 | K16: =J16 -> 0.1 | L16: =K16 -> 0.1 | M16: =L16 -> 0.1 | N16: =M16 -> 0.1 | ... P16: =O16 -> 0.1
B17: Integração com sistemas de monitoramento de saúde | C17: Foco na segurança e integração da plataforma. | D17: 6000 | E17: 233.8 | F17: =E17*(1+F16) -> 257.18 | G17: =F17*(1+G16) -> 282.898 | H17: =G17*(1+H16) -> 311.1878 | I17: =H17*(1+I16) -> 342.30658 | J17: =I17*(1+J16) -> 376.53724 | K17: =J17*(1+K16) -> 414.19096 | L17: =K17*(1+L16) -> 455.61006 | M17: =L17*(1+M16) -> 501.17106 | ... P17: =O17*(1+P16) -> 667.05869 | Q17: =SUM(E17:P17) -> 4999.6455
B18: Taxa de Crescimento de 10% | C18: Taxa de crescimento de investimento de 10% ao mês MOM | F18: 0.1 | G18: =F18 -> 0.1 | H18: =G18 -> 0.1 | I18: =H18 -> 0.1 | J18: =I18 -> 0.1 | K18: =J18 -> 0.1 | L18: =K18 -> 0.1 | M18: =L18 -> 0.1 | N18: =M18 -> 0.1 | ... P18: =O18 -> 0.1
B19: Teste | C19: Verificar as funcionalidades, realizar testes e possíveis correções | D19: 12000 | E19: 542.45 | F19: =E19*(1+F18) -> 596.695 | G19: =F19*(1+G18) -> 656.3645 | H19: =G19*(1+H18) -> 722.00095 | I19: =H19*(1+I18) -> 794.20105 | J19: =I19*(1+J18) -> 873.62115 | K19: =J19*(1+K18) -> 960.98326 | L19: =K19*(1+L18) -> 1057.0816 | M19: =L19*(1+M18) -> 1162.7897 | ... P19: =O19*(1+P18) -> 1547.6732 | Q19: =SUM(E19:P19) -> 11599.905
B20: Taxa de Crescimento de 10% | C20: Taxa de crescimento de investimento de 10% ao mês MOM | F20: 0.1 | G20: =F20 -> 0.1 | H20: =G20 -> 0.1 | I20: =H20 -> 0.1 | J20: =I20 -> 0.1 | K20: =J20 -> 0.1 | L20: =K20 -> 0.1 | M20: =L20 -> 0.1 | N20: =M20 -> 0.1 | ... P20: =O20 -> 0.1
B21: Lançamento (Stakeholders internos) | C21: Tudo que tange aos stakeholders | D21: 4000 | E21: 869.8 | F21: =E21*(1+F20) -> 956.78 | G21: =F21*(1+G20) -> 1052.458 | H21: =G21*(1+H20) -> 1157.7038 | I21: =H21*(1+I20) -> 1273.4742 | J21: =I21*(1+J20) -> 1400.8216 | K21: =J21*(1+K20) -> 1540.9038 | L21: =K21*(1+L20) -> 1694.9941 | M21: =L21*(1+M20) -> 1864.4935 | ... P21: =O21*(1+P20) -> 2481.6409 | Q21: =SUM(E21:P21) -> 18600.05
B22: Taxa de Crescimento de 10% | C22: Taxa de crescimento de investimento de 10% ao mês MOM | F22: 0.1 | G22: =F22 -> 0.1 | H22: =G22 -> 0.1 | I22: =H22 -> 0.1 | J22: =I22 -> 0.1 | K22: =J22 -> 0.1 | L22: =K22 -> 0.1 | M22: =L22 -> 0.1 | N22: =M22 -> 0.1 | ... P22: =O22 -> 0.1
B23: Pós-lançamento (Stakeholders internos) | C23: Tudo que tange o pós lançamento. | D23: 3000 | E23: 514.4 | F23: =E23*(1+F22) -> 565.84 | G23: =F23*(1+G22) -> 622.424 | H23: =G23*(1+H22) -> 684.6664 | I23: =H23*(1+I22) -> 753.13304 | J23: =I23*(1+J22) -> 828.44634 | K23: =J23*(1+K22) -> 911.29098 | L23: =K23*(1+L22) -> 1002.4201 | M23: =L23*(1+M22) -> 1102.6621 | ... P23: =O23*(1+P22) -> 1467.6432 | Q23: =SUM(E23:P23) -> 11000.076
B24: Taxa de Crescimento de 10% | C24: Taxa de crescimento de investimento de 10% ao mês MOM | F24: 0.1 | G24: =F24 -> 0.1 | H24: =G24 -> 0.1 | I24: =H24 -> 0.1 | J24: =I24 -> 0.1 | K24: =J24 -> 0.1 | L24: =K24 -> 0.1 | M24: =L24 -> 0.1 | N24: =M24 -> 0.1 | ... P24: =O24 -> 0.1
B25: Marketing e Divulgação - para o Mercado | C25: Todo processo de marketing e divulgação. | D25: 2000 | E25: 701.45 | F25: =E25*(1+F24) -> 771.595 | G25: =F25*(1+G24) -> 848.7545 | H25: =G25*(1+H24) -> 933.62995 | I25: =H25*(1+I24) -> 1026.9929 | J25: =I25*(1+J24) -> 1129.6922 | K25: =J25*(1+K24) -> 1242.6615 | L25: =K25*(1+L24) -> 1366.9276 | M25: =L25*(1+M24) -> 1503.6204 | ... P25: =O25*(1+P24) -> 2001.3187 | Q25: =SUM(E25:P25) -> 15000.006
B26: Taxa de Crescimento de 10% | C26: Taxa de crescimento de investimento de 10% ao mês MOM | F26: 0.1 | G26: =F26 -> 0.1 | H26: =G26 -> 0.1 | I26: =H26 -> 0.1 | J26: =I26 -> 0.1 | K26: =J26 -> 0.1 | L26: =K26 -> 0.1 | M26: =L26 -> 0.1 | N26: =M26 -> 0.1 | ... P26: =O26 -> 0.1
B27: Avaliação e Aperfeiçoamento | C27: Feedback e adapção | D27: 3000 | E27: 416.2 | F27: =E27*(1+F26) -> 457.82 | G27: =F27*(1+G26) -> 503.602 | H27: =G27*(1+H26) -> 553.9622 | I27: =H27*(1+I26) -> 609.35842 | J27: =I27*(1+J26) -> 670.29426 | K27: =J27*(1+K26) -> 737.32369 | L27: =K27*(1+L26) -> 811.05606 | M27: =L27*(1+M26) -> 892.16166 | ... P27: =O27*(1+P26) -> 1187.4672 | Q27: =SUM(E27:P27) -> 8900.1389
B28: Taxa de Crescimento de 10% | C28: Taxa de crescimento de investimento de 10% ao mês MOM | F28: 0.1 | G28: =F28 -> 0.1 | H28: =G28 -> 0.1 | I28: =H28 -> 0.1 | J28: =I28 -> 0.1 | K28: =J28 -> 0.1 | L28: =K28 -> 0.1 | M28: =L28 -> 0.1 | N28: =M28 -> 0.1 | ... P28: =O28 -> 0.1
B29: Expansão | C29: Feedback e adapção | D29: 2000 | E29: 701.45 | F29: =E29*(1+F28) -> 771.595 | G29: =F29*(1+G28) -> 848.7545 | H29: =G29*(1+H28) -> 933.62995 | I29: =H29*(1+I28) -> 1026.9929 | J29: =I29*(1+J28) -> 1129.6922 | K29: =J29*(1+K28) -> 1242.6615 | L29: =K29*(1+L28) -> 1366.9276 | M29: =L29*(1+M28) -> 1503.6204 | ... P29: =O29*(1+P28) -> 2001.3187 | Q29: =SUM(E29:P29) -> 15000.006
B32: Investimentos
B33: Custo de Implementação | D33: 0 | E33: 0 | F33: =E33 -> 0 | G33: =F33 -> 0 | H33: =G33 -> 0 | I33: =H33 -> 0 | J33: =I33 -> 0 | K33: =J33 -> 0 | L33: =K33 -> 0 | M33: =L33 -> 0 | ... P33: =O33 -> 0 | Q33: =SUM(D33:P33) -> 0
B34: Custo da Operação | F34: =E34 -> 0 | G34: =F34 -> 0 | H34: =G34 -> 0 | I34: =H34 -> 0 | J34: =I34 -> 0 | K34: =J34 -> 0 | L34: =K34 -> 0 | M34: =L34 -> 0 | ... P34: =O34 -> 0 | Q34: =SUM(D34:P34) -> 0
B35: Custos de Treinamento | F35: =E35 -> 0 | G35: =F35 -> 0 | H35: =G35 -> 0 | I35: =H35 -> 0 | J35: =I35 -> 0 | K35: =J35 -> 0 | L35: =K35 -> 0 | M35: =L35 -> 0 | ... P35: =O35 -> 0 | Q35: =SUM(D35:P35) -> 0
B36: Custo | F36: =E36 -> 0 | G36: =F36 -> 0 | H36: =G36 -> 0 | I36: =H36 -> 0 | J36: =I36 -> 0 | K36: =J36 -> 0 | L36: =K36 -> 0 | M36: =L36 -> 0 | ... P36: =O36 -> 0 | Q36: =SUM(D36:P36) -> 0
B37: Custo | F37: =E37 -> 0 | G37: =F37 -> 0 | H37: =G37 -> 0 | I37: =H37 -> 0 | J37: =I37 -> 0 | K37: =J37 -> 0 | L37: =K37 -> 0 | M37: =L37 -> 0 | ... P37: =O37 -> 0 | Q37: =SUM(D37:P37) -> 0
B38: Custo | F38: =E38 -> 0 | G38: =F38 -> 0 | H38: =G38 -> 0 | I38: =H38 -> 0 | J38: =I38 -> 0 | K38: =J38 -> 0 | L38: =K38 -> 0 | M38: =L38 -> 0 | ... P38: =O38 -> 0 | Q38: =SUM(D38:P38) -> 0
B39: Custo | F39: =E39 -> 0 | G39: =F39 -> 0 | H39: =G39 -> 0 | I39: =H39 -> 0 | J39: =I39 -> 0 | K39: =J39 -> 0 | L39: =K39 -> 0 | M39: =L39 -> 0 | ... P39: =O39 -> 0 | Q39: =SUM(D39:P39) -> 0
B40: Custo | F40: =E40 -> 0 | G40: =F40 -> 0 | H40: =G40 -> 0 | I40: =H40 -> 0 | J40: =I40 -> 0 | K40: =J40 -> 0 | L40: =K40 -> 0 | M40: =L40 -> 0 | ... P40: =O40 -> 0 | Q40: =SUM(D40:P40) -> 0
B41: Custo | F41: =E41 -> 0 | G41: =F41 -> 0 | H41: =G41 -> 0 | I41: =H41 -> 0 | J41: =I41 -> 0 | K41: =J41 -> 0 | L41: =K41 -> 0 | M41: =L41 -> 0 | ... P41: =O41 -> 0 | Q41: =SUM(D41:P41) -> 0
B42: Custo | F42: =E42 -> 0 | G42: =F42 -> 0 | H42: =G42 -> 0 | I42: =H42 -> 0 | J42: =I42 -> 0 | K42: =J42 -> 0 | L42: =K42 -> 0 | M42: =L42 -> 0 | ... P42: =O42 -> 0 | Q42: =SUM(D42:P42) -> 0
B43: Custo | F43: =E43 -> 0 | G43: =F43 -> 0 | H43: =G43 -> 0 | I43: =H43 -> 0 | J43: =I43 -> 0 | K43: =J43 -> 0 | L43: =K43 -> 0 | M43: =L43 -> 0 | ... P43: =O43 -> 0 | Q43: =SUM(D43:P43) -> 0
...

Sheet Realizado
B2: =Orcado!B2 -> Identificação do Projeto | E2: Mês
B3: Nome do Projeto | C3: =Param!C17 -> PI ADS4 - 2025 | E3: =Orcado!E3 -> 45891 | F3: =Orcado!F3 -> 45922 | G3: =Orcado!G3 -> 45952 | H3: =Orcado!H3 -> 45983 | I3: =Orcado!I3 -> 46013 | J3: =Orcado!J3 -> 46044 | K3: =Orcado!K3 -> 46075 | L3: =Orcado!L3 -> 46103 | ... P3: =Orcado!P3 -> 46225 | Q3: TOTAL
B4: Patrocinador | C4: =Param!C19 -> Cannoli | D4: 0 | E4: 1 | F4: =E4+1 -> 2 | G4: =F4+1 -> 3 | H4: =G4+1 -> 4 | I4: =H4+1 -> 5 | J4: =I4+1 -> 6 | K4: =J4+1 -> 7 | L4: =K4+1 -> 8 | M4: =L4+1 -> 9 | ... P4: =O4+1 -> 12
B5: Investimento Total | D5: =SUM(D9+D11+D13+D15+D17+D19+D21+D23+D25+D27+D29) -> 158109 | E5: =SUM(E39:E52)+E9+E11+E13+E15+E17+E19+E21+E23+E25+E27+E29 -> 7987.4 | F5: =SUM(F9+F11+F13+F15+F17+F19+F21+F23+F25+F27+F29) -> 8708.14 | G5: =SUM(G9+G11+G13+G15+G17+G19+G21+G23+G25+G27+G29) -> 9500.954 | H5: =SUM(H9+H11+H13+H15+H17+H19+H21+H23+H25+H27+H29) -> 10373.049 | I5: =SUM(I9+I11+I13+I15+I17+I19+I21+I23+I25+I27+I29) -> 11332.354 | J5: =SUM(J9+J11+J13+J15+J17+J19+J21+J23+J25+J27+J29) -> 12387.59 | K5: =SUM(K9+K11+K13+K15+K17+K19+K21+K23+K25+K27+K29) -> 13548.349 | L5: =SUM(L9+L11+L13+L15+L17+L19+L21+L23+L25+L27+L29) -> 14825.184 | M5: =SUM(M9+M11+M13+M15+M17+M19+M21+M23+M25+M27+M29) -> 16229.702 | ... P5: =SUM(P9+P11+P13+P15+P17+P19+P21+P23+P25+P27+P29) -> 21343.553 | Q5: =SUM(E5:P5) -> 163485.09
B6: Investimento Acumulado | D6: =D5 -> 158109 | E6: =D6+E5 -> 166096.4 | F6: =E6+F5 -> 174804.54 | G6: =F6+G5 -> 184305.49 | H6: =G6+H5 -> 194678.54 | I6: =H6+I5 -> 206010.9 | J6: =I6+J5 -> 218398.49 | K6: =J6+K5 -> 231946.84 | L6: =K6+L5 -> 246772.02 | ... P6: =O6+P5 -> 321594.09
B7: Realizado | C7: Explicação
B8: Investimento c/ taxa de crescimento
B9: =Orcado!B9 -> Iniciação | C9: Gasto referente ao start do projeto, desde o estudo, mapeamento de funcionalidade e formação de time | D9: 9360 | E9: 780 | F9: =E9*(1+F8) -> 780 | G9: =F9*(1+G8) -> 780 | H9: =G9*(1+H8) -> 780 | I9: =H9*(1+I8) -> 780 | J9: =I9*(1+J8) -> 780 | K9: =J9*(1+K8) -> 780 | L9: =K9*(1+L8) -> 780 | M9: =L9*(1+M8) -> 780 | ... P9: =O9*(1+P8) -> 780 | Q9: =SUM(E9:P9) -> 9360
F10: 0.1 | G10: 0.1 | H10: 0.1 | I10: 0.1 | J10: 0.1 | K10: 0.1 | L10: 0.1 | M10: 0.1 | N10: 0.1 | O10: 0.1 | P10: 0.1
B11: =Orcado!B11 -> Planejamento | C11: Tudo que tange o mapeamento inicial do planejamento, como plano de exercicio e requisitos, mapas de academias e parques e afins. | D11: 16680 | E11: 780 | F11: =E11*(1+F10) -> 858 | G11: =F11*(1+G10) -> 943.8 | H11: =G11*(1+H10) -> 1038.18 | I11: =H11*(1+I10) -> 1141.998 | J11: =I11*(1+J10) -> 1256.1978 | K11: =J11*(1+K10) -> 1381.8176 | L11: =K11*(1+L10) -> 1519.9993 | M11: =L11*(1+M10) -> 1671.9993 | ... P11: =O11*(1+P10) -> 2225.431 | Q11: =SUM(E11:P11) -> 16679.741
F12: 0.1 | G12: =F12 -> 0.1 | H12: =G12 -> 0.1 | I12: =H12 -> 0.1 | J12: =I12 -> 0.1 | K12: =J12 -> 0.1 | L12: =K12 -> 0.1 | M12: =L12 -> 0.1 | N12: =M12 -> 0.1 | ... P12: =O12 -> 0.1
B13: =Orcado!B13 -> Design e Prototipagem | C13: Todo processo que compete ao desenvolvimento da funcionalidade em sua camada de Wire, Layout, experiência, ou seja, UX. | D13: 14969 | E13: 700 | F13: =E13*(1+F12) -> 770 | G13: =F13*(1+G12) -> 847 | H13: =G13*(1+H12) -> 931.7 | I13: =H13*(1+I12) -> 1024.87 | J13: =I13*(1+J12) -> 1127.357 | K13: =J13*(1+K12) -> 1240.0927 | L13: =K13*(1+L12) -> 1364.102 | M13: =L13*(1+M12) -> 1500.5122 | ... P13: =O13*(1+P12) -> 1997.1817 | Q13: =SUM(E13:P13) -> 14968.999
F14: 0.1 | G14: =F14 -> 0.1 | H14: =G14 -> 0.1 | I14: =H14 -> 0.1 | J14: =I14 -> 0.1 | K14: =J14 -> 0.1 | L14: =K14 -> 0.1 | M14: =L14 -> 0.1 | N14: =M14 -> 0.1 | ... P14: =O14 -> 0.1
B15: =Orcado!B15 -> Desenvolvimento | C15: Desenvolvimento do frontend, backend e todo processo de desenvolvimento. | D15: 32000 | E15: 1700 | F15: =E15*(1+F14) -> 1870 | G15: =F15*(1+G14) -> 2057 | H15: =G15*(1+H14) -> 2262.7 | I15: =H15*(1+I14) -> 2488.97 | J15: =I15*(1+J14) -> 2737.867 | K15: =J15*(1+K14) -> 3011.6537 | L15: =K15*(1+L14) -> 3312.8191 | M15: =L15*(1+M14) -> 3644.101 | ... P15: =O15*(1+P14) -> 4850.2984 | Q15: =SUM(E15:P15) -> 36353.282
F16: 0.1 | G16: =F16 -> 0.1 | H16: =G16 -> 0.1 | I16: =H16 -> 0.1 | J16: =I16 -> 0.1 | K16: =J16 -> 0.1 | L16: =K16 -> 0.1 | M16: =L16 -> 0.1 | N16: =M16 -> 0.1 | ... P16: =O16 -> 0.1
B17: =Orcado!B17 -> Integração com sistemas de monitoramento de saúde | C17: Foco na segurança e integração da plataforma. | D17: 5000 | E17: 203 | F17: =E17*(1+F16) -> 223.3 | G17: =F17*(1+G16) -> 245.63 | H17: =G17*(1+H16) -> 270.193 | I17: =H17*(1+I16) -> 297.2123 | J17: =I17*(1+J16) -> 326.93353 | K17: =J17*(1+K16) -> 359.62688 | L17: =K17*(1+L16) -> 395.58957 | M17: =L17*(1+M16) -> 435.14853 | ... P17: =O17*(1+P16) -> 579.18269 | Q17: =SUM(E17:P17) -> 4341.0096
F18: 0.1 | G18: =F18 -> 0.1 | H18: =G18 -> 0.1 | I18: =H18 -> 0.1 | J18: =I18 -> 0.1 | K18: =J18 -> 0.1 | L18: =K18 -> 0.1 | M18: =L18 -> 0.1 | N18: =M18 -> 0.1 | ... P18: =O18 -> 0.1
B19: =Orcado!B19 -> Teste | C19: Verificar as funcionalidades, realizar testes e possíveis correções | D19: 11600 | E19: 520 | F19: =E19*(1+F18) -> 572 | G19: =F19*(1+G18) -> 629.2 | H19: =G19*(1+H18) -> 692.12 | I19: =H19*(1+I18) -> 761.332 | J19: =I19*(1+J18) -> 837.4652 | K19: =J19*(1+K18) -> 921.21172 | L19: =K19*(1+L18) -> 1013.3329 | M19: =L19*(1+M18) -> 1114.6662 | ... P19: =O19*(1+P18) -> 1483.6207 | Q19: =SUM(E19:P19) -> 11119.828
F20: 0.1 | G20: =F20 -> 0.1 | H20: =G20 -> 0.1 | I20: =H20 -> 0.1 | J20: =I20 -> 0.1 | K20: =J20 -> 0.1 | L20: =K20 -> 0.1 | M20: =L20 -> 0.1 | N20: =M20 -> 0.1 | ... P20: =O20 -> 0.1
B21: =Orcado!B21 -> Lançamento (Stakeholders internos) | C21: Tudo que tange aos stakeholders | D21: 18600 | E21: 950 | F21: =E21*(1+F20) -> 1045 | G21: =F21*(1+G20) -> 1149.5 | H21: =G21*(1+H20) -> 1264.45 | I21: =H21*(1+I20) -> 1390.895 | J21: =I21*(1+J20) -> 1529.9845 | K21: =J21*(1+K20) -> 1682.983 | L21: =K21*(1+L20) -> 1851.2812 | M21: =L21*(1+M20) -> 2036.4094 | ... P21: =O21*(1+P20) -> 2710.4609 | Q21: =SUM(E21:P21) -> 20315.07
F22: 0.1 | G22: =F22 -> 0.1 | H22: =G22 -> 0.1 | I22: =H22 -> 0.1 | J22: =I22 -> 0.1 | K22: =J22 -> 0.1 | L22: =K22 -> 0.1 | M22: =L22 -> 0.1 | N22: =M22 -> 0.1 | ... P22: =O22 -> 0.1
B23: =Orcado!B23 -> Pós-lançamento (Stakeholders internos) | C23: Tudo que tange o pós lançamento. | D23: 11000 | E23: 514.4 | F23: =E23*(1+F22) -> 565.84 | G23: =F23*(1+G22) -> 622.424 | H23: =G23*(1+H22) -> 684.6664 | I23: =H23*(1+I22) -> 753.13304 | J23: =I23*(1+J22) -> 828.44634 | K23: =J23*(1+K22) -> 911.29098 | L23: =K23*(1+L22) -> 1002.4201 | M23: =L23*(1+M22) -> 1102.6621 | ... P23: =O23*(1+P22) -> 1467.6432 | Q23: =SUM(E23:P23) -> 11000.076
F24: 0.1 | G24: =F24 -> 0.1 | H24: =G24 -> 0.1 | I24: =H24 -> 0.1 | J24: =I24 -> 0.1 | K24: =J24 -> 0.1 | L24: =K24 -> 0.1 | M24: =L24 -> 0.1 | N24: =M24 -> 0.1 | ... P24: =O24 -> 0.1
B25: =Orcado!B25 -> Marketing e Divulgação - para o Mercado | C25: Todo processo de marketing e divulgação. | D25: 15000 | E25: 720 | F25: =E25*(1+F24) -> 792 | G25: =F25*(1+G24) -> 871.2 | H25: =G25*(1+H24) -> 958.32 | I25: =H25*(1+I24) -> 1054.152 | J25: =I25*(1+J24) -> 1159.5672 | K25: =J25*(1+K24) -> 1275.5239 | L25: =K25*(1+L24) -> 1403.0763 | M25: =L25*(1+M24) -> 1543.3839 | ... P25: =O25*(1+P24) -> 2054.244 | Q25: =SUM(E25:P25) -> 15396.684
F26: 0.1 | G26: =F26 -> 0.1 | H26: =G26 -> 0.1 | I26: =H26 -> 0.1 | J26: =I26 -> 0.1 | K26: =J26 -> 0.1 | L26: =K26 -> 0.1 | M26: =L26 -> 0.1 | N26: =M26 -> 0.1 | ... P26: =O26 -> 0.1
B27: =Orcado!B27 -> Avaliação e Aperfeiçoamento | C27: Feedback e adapção | D27: 8900 | E27: 410 | F27: =E27*(1+F26) -> 451 | G27: =F27*(1+G26) -> 496.1 | H27: =G27*(1+H26) -> 545.71 | I27: =H27*(1+I26) -> 600.281 | J27: =I27*(1+J26) -> 660.3091 | K27: =J27*(1+K26) -> 726.34001 | L27: =K27*(1+L26) -> 798.97401 | M27: =L27*(1+M26) -> 878.87141 | ... P27: =O27*(1+P26) -> 1169.7778 | Q27: =SUM(E27:P27) -> 8767.5563
F28: 0.1 | G28: =F28 -> 0.1 | H28: =G28 -> 0.1 | I28: =H28 -> 0.1 | J28: =I28 -> 0.1 | K28: =J28 -> 0.1 | L28: =K28 -> 0.1 | M28: =L28 -> 0.1 | N28: =M28 -> 0.1 | ... P28: =O28 -> 0.1
B29: =Orcado!B29 -> Expansão | C29: Feedback e adapção | D29: 15000 | E29: 710 | F29: =E29*(1+F28) -> 781 | G29: =F29*(1+G28) -> 859.1 | H29: =G29*(1+H28) -> 945.01 | I29: =H29*(1+I28) -> 1039.511 | J29: =I29*(1+J28) -> 1143.4621 | K29: =J29*(1+K28) -> 1257.8083 | L29: =K29*(1+L28) -> 1383.5891 | M29: =L29*(1+M28) -> 1521.9481 | ... P29: =O29*(1+P28) -> 2025.7129 | Q29: =SUM(E29:P29) -> 15182.841
B38: Investimentos
B39: =Orcado!B33 -> Custo de Implementação | D39: 0 | E39: 0 | F39: =E39 -> 0 | G39: =F39 -> 0 | H39: =G39 -> 0 | I39: =H39 -> 0 | J39: =I39 -> 0 | K39: =J39 -> 0 | L39: =K39 -> 0 | M39: =L39 -> 0 | ... P39: =O39 -> 0 | Q39: =SUM(D39:P39) -> 0
B40: =Orcado!B34 -> Custo da Operação | F40: =E40 -> 0 | G40: =F40 -> 0 | H40: =G40 -> 0 | I40: =H40 -> 0 | J40: =I40 -> 0 | K40: =J40 -> 0 | L40: =K40 -> 0 | M40: =L40 -> 0 | ... P40: =O40 -> 0 | Q40: =SUM(D40:P40) -> 0
B41: =Orcado!B35 -> Custos de Treinamento | F41: =E41 -> 0 | G41: =F41 -> 0 | H41: =G41 -> 0 | I41: =H41 -> 0 | J41: =I41 -> 0 | K41: =J41 -> 0 | L41: =K41 -> 0 | M41: =L41 -> 0 | ... P41: =O41 -> 0 | Q41: =SUM(D41:P41) -> 0
B42: =Orcado!B36 -> Custo | F42: =E42 -> 0 | G42: =F42 -> 0 | H42: =G42 -> 0 | I42: =H42 -> 0 | J42: =I42 -> 0 | K42: =J42 -> 0 | L42: =K42 -> 0 | M42: =L42 -> 0 | ... P42: =O42 -> 0 | Q42: =SUM(D42:P42) -> 0
B43: =Orcado!B37 -> Custo | F43: =E43 -> 0 | G43: =F43 -> 0 | H43: =G43 -> 0 | I43: =H43 -> 0 | J43: =I43 -> 0 | K43: =J43 -> 0 | L43: =K43 -> 0 | M43: =L43 -> 0 | ... P43: =O43 -> 0 | Q43: =SUM(D43:P43) -> 0
B44: =Orcado!B38 -> Custo | F44: =E44 -> 0 | G44: =F44 -> 0 | H44: =G44 -> 0 | I44: =H44 -> 0 | J44: =I44 -> 0 | K44: =J44 -> 0 | L44: =K44 -> 0 | M44: =L44 -> 0 | ... P44: =O44 -> 0 | Q44: =SUM(D44:P44) -> 0
B45: =Orcado!B39 -> Custo | F45: =E45 -> 0 | G45: =F45 -> 0 | H45: =G45 -> 0 | I45: =H45 -> 0 | J45: =I45 -> 0 | K45: =J45 -> 0 | L45: =K45 -> 0 | M45: =L45 -> 0 | ... P45: =O45 -> 0 | Q45: =SUM(D45:P45) -> 0
B46: =Orcado!B40 -> Custo | F46: =E46 -> 0 | G46: =F46 -> 0 | H46: =G46 -> 0 | I46: =H46 -> 0 | J46: =I46 -> 0 | K46: =J46 -> 0 | L46: =K46 -> 0 | M46: =L46 -> 0 | ... P46: =O46 -> 0 | Q46: =SUM(D46:P46) -> 0
B47: =Orcado!B41 -> Custo | F47: =E47 -> 0 | G47: =F47 -> 0 | H47: =G47 -> 0 | I47: =H47 -> 0 | J47: =I47 -> 0 | K47: =J47 -> 0 | L47: =K47 -> 0 | M47: =L47 -> 0 | ... P47: =O47 -> 0 | Q47: =SUM(D47:P47) -> 0
B48: =Orcado!B42 -> Custo | F48: =E48 -> 0 | G48: =F48 -> 0 | H48: =G48 -> 0 | I48: =H48 -> 0 | J48: =I48 -> 0 | K48: =J48 -> 0 | L48: =K48 -> 0 | M48: =L48 -> 0 | ... P48: =O48 -> 0 | Q48: =SUM(D48:P48) -> 0
B49: =Orcado!B43 -> Custo | F49: =E49 -> 0 | G49: =F49 -> 0 | H49: =G49 -> 0 | I49: =H49 -> 0 | J49: =I49 -> 0 | K49: =J49 -> 0 | L49: =K49 -> 0 | M49: =L49 -> 0 | ... P49: =O49 -> 0 | Q49: =SUM(D49:P49) -> 0
...

Sheet Gráfico -Status
B2: Períodos | C2: No Período (R$) | E2: Acumulado (R$) | G2: Desvio (R$) | H2: Desvio %
B3: Mês | C3: Orçado | D3: Realizado | E3: Orçado | F3: Realizado | G3: Diferença dos realizados
B4: 0 | C4: =HLOOKUP($B4,Orcado!$D$4:$P$5,2,FALSE) -> 110000 | D4: =HLOOKUP($B4,Realizado!$D$4:$P$5,2,FALSE) -> 158109 | E4: =C4 -> 110000 | F4: =D4 -> 158109 | G4: =F4-E4 -> 48109 | H4: =IF(E4=0,"",F4/E4-1) -> 0.43735455
B5: =B4+1 -> 1 | C5: =HLOOKUP($B5,Orcado!$D$4:$P$5,2,FALSE) -> 10388.23 | D5: =HLOOKUP($B5,Realizado!$D$4:$P$5,2,FALSE) -> 7987.4 | E5: =E4+C5 -> 120388.23 | F5: =F4+D5 -> 166096.4 | G5: =F5-E5 -> 45708.17 | H5: =F5/E5-1 -> 0.37967308
B6: =B5+1 -> 2 | C6: =HLOOKUP($B6,Orcado!$D$4:$P$5,2,FALSE) -> 10305.458 | D6: =HLOOKUP($B6,Realizado!$D$4:$P$5,2,FALSE) -> 8708.14 | E6: =E5+C6 -> 130693.69 | F6: =F5+D6 -> 174804.54 | G6: =F6-E6 -> 44110.852 | H6: =F6/E6-1 -> 0.33751325
B7: =B6+1 -> 3 | C7: =HLOOKUP($B7,Orcado!$D$4:$P$5,2,FALSE) -> 7986.0038 | D7: =HLOOKUP($B7,Realizado!$D$4:$P$5,2,FALSE) -> 9500.954 | E7: =E6+C7 -> 138679.69 | F7: =F6+D7 -> 184305.49 | G7: =F7-E7 -> 45625.802 | H7: =F7/E7-1 -> 0.32900132
B8: =B7+1 -> 4 | C8: =HLOOKUP($B8,Orcado!$D$4:$P$5,2,FALSE) -> 8234.6042 | D8: =HLOOKUP($B8,Realizado!$D$4:$P$5,2,FALSE) -> 10373.049 | E8: =E7+C8 -> 146914.3 | F8: =F7+D8 -> 194678.54 | G8: =F8-E8 -> 47764.247 | H8: =F8/E8-1 -> 0.3251164
B9: =B8+1 -> 5 | C9: =HLOOKUP($B9,Orcado!$D$4:$P$5,2,FALSE) -> 9058.0646 | D9: =HLOOKUP($B9,Realizado!$D$4:$P$5,2,FALSE) -> 11332.354 | E9: =E8+C9 -> 155972.36 | F9: =F8+D9 -> 206010.9 | G9: =F9-E9 -> 50038.537 | H9: =F9/E9-1 -> 0.32081669
B10: =B9+1 -> 6 | C10: =HLOOKUP($B10,Orcado!$D$4:$P$5,2,FALSE) -> 9963.8711 | D10: =HLOOKUP($B10,Realizado!$D$4:$P$5,2,FALSE) -> 12387.59 | E10: =E9+C10 -> 165936.23 | F10: =F9+D10 -> 218398.49 | G10: =F10-E10 -> 52462.256 | H10: =F10/E10-1 -> 0.31615914
B11: =B10+1 -> 7 | C11: =HLOOKUP($B11,Orcado!$D$4:$P$5,2,FALSE) -> 10960.258 | D11: =HLOOKUP($B11,Realizado!$D$4:$P$5,2,FALSE) -> 13548.349 | E11: =E10+C11 -> 176896.49 | F11: =F10+D11 -> 231946.84 | G11: =F11-E11 -> 55050.346 | H11: =F11/E11-1 -> 0.3112009
B12: =B11+1 -> 8 | C12: =HLOOKUP($B12,Orcado!$D$4:$P$5,2,FALSE) -> 12056.284 | D12: =HLOOKUP($B12,Realizado!$D$4:$P$5,2,FALSE) -> 14825.184 | E12: =E11+C12 -> 188952.77 | F12: =F11+D12 -> 246772.02 | G12: =F12-E12 -> 57819.246 | H12: =F12/E12-1 -> 0.3059984
B13: =B12+1 -> 9 | C13: =HLOOKUP($B13,Orcado!$D$4:$P$5,2,FALSE) -> 13261.912 | D13: =HLOOKUP($B13,Realizado!$D$4:$P$5,2,FALSE) -> 16229.702 | E13: =E12+C13 -> 202214.69 | F13: =F12+D13 -> 263001.72 | G13: =F13-E13 -> 60787.036 | H13: =F13/E13-1 -> 0.30060643
B14: =B13+1 -> 10 | C14: =HLOOKUP($B14,Orcado!$D$4:$P$5,2,FALSE) -> 14588.104 | D14: =HLOOKUP($B14,Realizado!$D$4:$P$5,2,FALSE) -> 17774.672 | E14: =E13+C14 -> 216802.79 | F14: =F13+D14 -> 280776.39 | G14: =F14-E14 -> 63973.604 | H14: =F14/E14-1 -> 0.2950774
B15: =B14+1 -> 11 | C15: =HLOOKUP($B15,Orcado!$D$4:$P$5,2,FALSE) -> 16046.914 | D15: =HLOOKUP($B15,Realizado!$D$4:$P$5,2,FALSE) -> 19474.139 | E15: =E14+C15 -> 232849.7 | F15: =F14+D15 -> 300250.53 | G15: =F15-E15 -> 67400.83 | H15: =F15/E15-1 -> 0.28946066
B16: =B15+1 -> 12 | C16: =HLOOKUP($B16,Orcado!$D$4:$P$5,2,FALSE) -> 17651.605 | D16: =HLOOKUP($B16,Realizado!$D$4:$P$5,2,FALSE) -> 21343.553 | E16: =E15+C16 -> 250501.31 | F16: =F15+D16 -> 321594.09 | G16: =F16-E16 -> 71092.778 | H16: =F16/E16-1 -> 0.28380202
B17: Total | C17: =SUM(C4:C16) -> 250501.31 | D17: =SUM(D4:D16) -> 321594.09
B18: Saldo Final | C18: =C17-D17 -> -71092.778

Sheet Param
B2: Variável | C2: Tipo de Benefício | D2: Custo do Capital
B3: Explicação | D3: Retorno Requerido do Investimento
B4: Domínio ou Valor | C4: Aumento de Receita | D4: 0.06
C5: Aumento de Produtividade
C6: Aumento da Capacidade Produtiva
C7: Redução do Turn-over
C8: Redução de retrabalho
C9: Redução dos custos da não qualidade
C10: Redução das reclamações dos clientes
C11: Redução dos custos
B15: Parametros a serem configurados inicialmente
B16: Projeto
B17: Nome do projeto | C17: PI ADS4 - 2025
B18: Mês de início | C18: 45891
B19: Patrocinador | C19: Cannoli

Sheet Capa
B5: Informações sobre o projeto
B6: Projeto | E6: Calogic
B7: Gerente Responsável | E7: Kaique Neres de Oliveira
B8: Data da avaliação | E8: 45944
B9: Histórico da avaliação de riscos
B10: 45908 | C10: Falhas no escopo levam atrasos e o aumento de custos. Reforçar análise de requisitos e controle de mudanças.
B11: 45915 | C11: Falhas na autenticação podem permitir acesso indevido a dados e sistemas. Recomenda-se aplicar autenticação multifator (MFA) e revisão de permissões de usuários.
B12: 45915 | C12: A ausência de plano estruturado prejudica a conformidade e resposta a incidentes. É necessário criar um plano de segurança formal e designar um responsável (DPO).
B13: 45922 | C13: APIs expostas sem controle de acesso são portas de entrada para ataques. Implementar tokens seguros (OAuth2), revisão de endpoints e testes de penetração.
B14: 45922 | C14: O chatbot pode vazar dados pessoais se não houver filtragem e anonimização. Reforçar logs, revisão de prompts e uso de máscaras de dados.
B15: 45922 | C15: Afeta diretamente a continuidade do sistema. É importante definir redundância e planos de contingência (multi-cloud ou backups offline).
B16: 45929 | C16: Exige revisão de código, aplicação de WAF e monitoramento contínuo. Implementar varreduras automáticas de vulnerabilidade.
B17: 45929 | C17: O risco envolve exposição de informações sensíveis e violações à LGPD. Exige medidas imediatas como criptografia de dados, revisão de políticas de privacidade e treinamento da equipe.
B18: 45936 | C18: Pode causar desalinhamento de expectativas e decisões incorretas. Reavaliar a matriz de stakeholders e atualizar periodicamente.
B19: 45936 | C19: Provoca instabilidade no desenvolvimento. Implantar controle de versionamento e processo formal de gestão de mudanças (change request).

Sheet Identificar
A1: Identificação dos Riscos | AF1: Probabilidade | AI1: Impacto
A4: =Capa!E6 -> Calogic
AF5: Muito Baixa - 1 | AG5: 1 | AI5: Muito Baixo - 1 | AJ5: 1
A6: ID | B6: Fase ou | D6: Declaração do Risco | G6: Resp. | H6: Estratégia de Resposta | I6: Plano de Prevenção | J6: Plano de Contingência | L6: Severidade (X,Y) | AF6: Baixa - 2 | AG6: 2 | AI6: Muito Baixo - 2 | AJ6: 2
B7: Recurso | C7: Classificação | D7: CAUSA (Começa a frase com "Como Resultado ...") | E7: RISCO (Começar a frase com "Pode ocorrer ...") | F7: CONSEQUÊNCIA (Começar a frase com "O que acarretaria ...") | K7: Riscos Colaterais | AF7: Moderada - 3 | AG7: 3 | AI7: Baixo - 3 | AJ7: 3
A8: R01 | B8: Planejamento | C8: Falhas | D8: Como resultado da falha da equipe e do gerente do projeto. | E8: Pode ocorrer de aumentar os custos e os atrasos, além de acabar com a expectativa do stakeholder. | F8: O que acarretaria capacitação para o lançamento do sistema. | H8: Mitigar | I8: Realizar reuniões, definir responsabilidades e cronogramas que sigam as datas corretamente. | J8: Replanejar o cronograma, as tarefas e contratar apoio caso necessário. | K8: Atraso no projeto e aumento nos custos | L8: =Qualificar!K8 -> 0.01 | AF8: Alta - 4 | AG8: 4 | AI8: Baixo - 4 | AJ8: 4
A9: R02 | B9: Segurança | C9: Falhas | D9: Como resultado de não implementação de segurança de autenticação. | E9: Pode ocorrer acesso indevido. | F9: O que acarretaria vazamento de dados e vulnerabilidade nos sistemas. | H9: Evitar | I9: Implementar autenticação multifator e criptografia; testar vulnerabilidades. | J9: Bloquear contas comprometidas; restaurar backups; reforçar auditoria de acessos. | L9: =Qualificar!K9 -> 0.32
A10: R03 | B10: Planejamento | C10: Ausência | D10: Como resultado da ausência de um plano de respostas a incidentes. | E10: Pode ocorrer a lentidão da resposta à ataques. | F10: O que acarretaria aumento da exposição. | H10: Mitigar | I10: Criar e documentar plano de resposta; simular ataques (testes de penetração). | J10: Ativar equipe de resposta rápida; priorizar mitigação e comunicação com stakeholders. | L10: =Qualificar!K10 -> 0.16
A11: R04 | B11: Segurança | C11: Vulnerabilidade | D11: Como resultado da falta de controle de acesso. | E11: Pode ocorrer acesso indevido e ataques. | F11: O que acarretaria vazamento de dados e vulnerabilidade nos sistemas. | H11: Evitar | I11: Configurar níveis de permissão; revisar perfis trimestralmente. | J11: Revogar acessos suspeitos; revisar logs; aplicar medidas disciplinares. | L11: =Qualificar!K11 -> 0.32
A12: R05 | B12: Segurança | C12: Vazamento | D12: Como resultado da não anonimização de dados. | E12: Pode ocorrer vazamento de dados pessoais. | F12: O que acarretaria exposição desses dados pessoais. | H12: Transferir | I12: Anonimizar dados sensíveis; revisar políticas LGPD. | J12: Acionar equipe jurídica; comunicar autoridade competente; corrigir falhas de segurança. | L12: =Qualificar!K12 -> 0.32
A13: R06 | B13: Disponibilidade | C13: Redundância | D13: Como resultado da falta de redundância e backups. | E13: Pode ocorrer comprometimento do sistema. | F13: O que acarretaria indisponibilidade do sistema. | H13: Mitigar | I13: Implementar backups automáticos e redundantes; testar restauração mensal. | J13: Restaurar sistema a partir do backup mais recente; comunicar usuários sobre indisponibilidade. | L13: =Qualificar!K13 -> 0.16
A14: R07 | B14: Sustentação | C14: Melhorias contínuas | D14: Como resultado de falta de avaliação contínua. | E14: Pode ocorrer bugs não tratados e obsoleineidade do sistema. | F14: O que acarretaria baixa satisfação do usuário. | H14: Mitigar | I14: Adotar ciclos de revisão contínua (sprints); testes automatizados. | J14: Suspender versões instáveis; corrigir falhas emergenciais. | L14: =Qualificar!K14 -> 0.02
A15: R08 | B15: Segurança | C15: Legal | D15: Como resultado da não observação das leis atuais. | E15: Pode ocorrer exposição de informações. | F15: O que acarretaria violação da LGPD e multas. | H15: Transferir | I15: Revisar legislação aplicável; aplicar políticas de privacidade. | J15: Consultar assessoria jurídica; ajustar documentação e avisos legais. | L15: =Qualificar!K15 -> 0.32
A16: R09 | B16: Planejamento | C16: Melhorias contínuas | D16: Como resultado da falta de engajamento dos parceiros. | E16: Pode ocorrer que os stakeholders se frustem. | F16: O que acarretaria desconfiança do produto. | H16: Aceitar | I16: Promover reuniões e relatórios periódicos; manter comunicação transparente. | J16: Realinhar expectativas; reforçar comunicação e demonstrar entregas.
A17: R10 | B17: Validação | C17: GMUD | D17: Como resultado da falta de gestão de mudanças. | E17: Pode ocorrer atraso no desenvolvimento. | F17: O que acarretaria atrasos e instabilidades. | H17: Mitigar | I17: Implantar processo formal de controle de mudanças (Change Management). | J17: Reverter versão anterior (rollback); ajustar documentação técnica.
A18: R11
A19: R12
A20: R13
A21: R14
A22: R15
A23: R16
A24: R17
A25: R18
A26: R19 | L26: =Qualificar!K26
A27: R20 | L27: =Qualificar!K27

Sheet Qualificar
A1: Qualificação dos Riscos | AF1: Probabilidade | AI1: Impacto
K2: Base Custo | M2: 10000 | N2: R$
K3: Base Prazo | M3: 30 | N3: dias úteis
A4: =Identificar!A4 -> Calogic
AF5: Muito Baixa - 1 | AG5: 1 | AI5: Muito Baixo - 1 | AJ5: 1
A6: ID | B6: Declaração do Risco | E6: Resp. | F6: Probabilidade do risco virar incidente (Y) | G6: Avaliação de Impacto (X) | K6: Severidade (Y,X) | M6: Custo | N6: Prazo | AF6: Baixa - 2 | AG6: 2 | AI6: Muito Baixo - 2 | AJ6: 2
B7: CAUSA (Começa a frase com "Como Resultado ...") | C7: RISCO (Começar a frase com "Pode ocorrer ...") | D7: CONSEQÜÊNCIA (Começar a frase com "O que acarretaria ...") | G7: Aumento no Custo (X1) | H7: Desvio no Cronograma (X2) | I7: (X1*X2) | J7: Resultado do Impacto (X1+X2) | L7: Riscos Colaterais | AF7: Moderada - 3 | AG7: 3 | AI7: Baixo - 3 | AJ7: 3
A8: =IF(Identificar!A8<>"",Identificar!A8,"") -> R01 | B8: =IF(Identificar!D8<>"",Identificar!D8,"") -> Como resultado da falha da equipe e do gerente do projeto. | C8: =IF(Identificar!E8<>"",Identificar!E8,"") -> Pode ocorrer de aumentar os custos e os atrasos, além de acabar com a expectativa do stakeholder. | D8: =IF(Identificar!F8<>"",Identificar!F8,"") -> O que acarretaria capacitação para o lançamento do sistema. | E8: =IF(Identificar!G8<>"",Identificar!G8,"") | F8: Baixa - 0,1 | G8: Menor que 5% - 1,10 | H8: Menor que 5% - 2,10 | I8: =IF(G8<>"",IF(H8<>"",RIGHT(G8,4)*RIGHT(H8,4),""),"") -> 2.31 | J8: =IF(I8<>"",VLOOKUP(I8,'[8]Sensibilidade ao Risco'!$E$2:$F$30,2,FALSE),"") -> Baixa - 0,10 | K8: =IF(F8<>"",IF(J8<>"",(RIGHT(J8,3))*(RIGHT(F8,3)),""),"") -> 0.01 | L8: Atraso no projeto e aumento nos custos | M8: =ROUNDUP(Quantificar!G8/Qualificar!$M$2,2) -> 1.5 | N8: =ROUNDUP(Quantificar!H8/Qualificar!$M$3,2) -> 0.5 | AF8: Alta - 4 | AG8: 4 | AI8: Baixo - 4 | AJ8: 4
A9: =IF(Identificar!A9<>"",Identificar!A9,"") -> R02 | B9: =IF(Identificar!D9<>"",Identificar!D9,"") -> Como resultado de não implementação de segurança de autenticação. | C9: =IF(Identificar!E9<>"",Identificar!E9,"") -> Pode ocorrer acesso indevido. | D9: =IF(Identificar!F9<>"",Identificar!F9,"") -> O que acarretaria vazamento de dados e vulnerabilidade nos sistemas. | E9: =IF(Identificar!G9<>"",Identificar!G9,"") | F9: Muito Alta - 0,8 | G9: Maior que 20% - 1,80 | H9: Menor que 5% - 2,10 | I9: =IF(G9<>"",IF(H9<>"",RIGHT(G9,4)*RIGHT(H9,4),""),"") -> 3.78 | J9: =IF(I9<>"",VLOOKUP(I9,'[8]Sensibilidade ao Risco'!$E$2:$F$30,2,FALSE),"") -> Alta - 0,40 | K9: =IF(F9<>"",IF(J9<>"",(RIGHT(J9,3))*(RIGHT(F9,3)),""),"") -> 0.32 | M9: =ROUNDUP(Quantificar!G9/Qualificar!$M$2,2) -> 1 | N9: =ROUNDUP(Quantificar!H9/Qualificar!$M$3,2) -> 0.34
A10: =IF(Identificar!A10<>"",Identificar!A10,"") -> R03 | B10: =IF(Identificar!D10<>"",Identificar!D10,"") -> Como resultado da ausência de um plano de respostas a incidentes. | C10: =IF(Identificar!E10<>"",Identificar!E10,"") -> Pode ocorrer a lentidão da resposta à ataques. | D10: =IF(Identificar!F10<>"",Identificar!F10,"") -> O que acarretaria aumento da exposição. | E10: =IF(Identificar!G10<>"",Identificar!G10,"") | F10: Alta - 0,4 | G10: Entre 10% e 20% - 1,40 | H10: Menor que 5% - 2,10 | I10: =IF(G10<>"",IF(H10<>"",RIGHT(G10,4)*RIGHT(H10,4),""),"") -> 2.94 | J10: =IF(I10<>"",VLOOKUP(I10,'[8]Sensibilidade ao Risco'!$E$2:$F$30,2,FALSE),"") -> Alta - 0,40 | K10: =IF(F10<>"",IF(J10<>"",(RIGHT(J10,3))*(RIGHT(F10,3)),""),"") -> 0.16 | M10: =ROUNDUP(Quantificar!G10/Qualificar!$M$2,2) -> 1.2 | N10: =ROUNDUP(Quantificar!H10/Qualificar!$M$3,2) -> 0.4
A11: =IF(Identificar!A11<>"",Identificar!A11,"") -> R04 | B11: =IF(Identificar!D11<>"",Identificar!D11,"") -> Como resultado da falta de controle de acesso. | C11: =IF(Identificar!E11<>"",Identificar!E11,"") -> Pode ocorrer acesso indevido e ataques. | D11: =IF(Identificar!F11<>"",Identificar!F11,"") -> O que acarretaria vazamento de dados e vulnerabilidade nos sistemas. | E11: =IF(Identificar!G11<>"",Identificar!G11,"") | F11: Alta - 0,4 | G11: Entre 10% e 20% - 1,40 | H11: Entre 10% e 20% - 2,40 | I11: =IF(G11<>"",IF(H11<>"",RIGHT(G11,4)*RIGHT(H11,4),""),"") -> 3.36 | J11: =IF(I11<>"",VLOOKUP(I11,'[8]Sensibilidade ao Risco'!$E$2:$F$30,2,FALSE),"") -> Muito Alta - 0,80 | K11: =IF(F11<>"",IF(J11<>"",(RIGHT(J11,3))*(RIGHT(F11,3)),""),"") -> 0.32 | M11: =ROUNDUP(Quantificar!G11/Qualificar!$M$2,2) -> 2 | N11: =ROUNDUP(Quantificar!H11/Qualificar!$M$3,2) -> 0.67
A12: =IF(Identificar!A12<>"",Identificar!A12,"") -> R05 | B12: =IF(Identificar!D12<>"",Identificar!D12,"") -> Como resultado da não anonimização de dados. | C12: =IF(Identificar!E12<>"",Identificar!E12,"") -> Pode ocorrer vazamento de dados pessoais. | D12: =IF(Identificar!F12<>"",Identificar!F12,"") -> O que acarretaria exposição desses dados pessoais. | E12: =IF(Identificar!G12<>"",Identificar!G12,"") | F12: Alta - 0,4 | G12: Maior que 20% - 1,80 | H12: Entre 5% e 10% - 2,20 | I12: =IF(G12<>"",IF(H12<>"",RIGHT(G12,4)*RIGHT(H12,4),""),"") -> 3.96 | J12: =IF(I12<>"",VLOOKUP(I12,'[8]Sensibilidade ao Risco'!$E$2:$F$30,2,FALSE),"") -> Muito Alta - 0,80 | K12: =IF(F12<>"",IF(J12<>"",(RIGHT(J12,3))*(RIGHT(F12,3)),""),"") -> 0.32 | M12: =ROUNDUP(Quantificar!G12/Qualificar!$M$2,2) -> 2.5 | N12: =ROUNDUP(Quantificar!H12/Qualificar!$M$3,2) -> 0.84
